[2022-03-16 18:53:17,543] {processor.py:163} INFO - Started process (PID=18332) to work on /opt/airflow/dags/gcs_ingestion_dag_NEWDATA.py
[2022-03-16 18:53:17,544] {processor.py:642} INFO - Processing file /opt/airflow/dags/gcs_ingestion_dag_NEWDATA.py for tasks to queue
[2022-03-16 18:53:17,544] {logging_mixin.py:109} INFO - [2022-03-16 18:53:17,544] {dagbag.py:500} INFO - Filling up the DagBag from /opt/airflow/dags/gcs_ingestion_dag_NEWDATA.py
[2022-03-16 18:53:18,034] {processor.py:654} INFO - DAG(s) dict_keys(['gcs_ingestion_dag_v02']) retrieved from /opt/airflow/dags/gcs_ingestion_dag_NEWDATA.py
[2022-03-16 18:53:18,219] {logging_mixin.py:109} INFO - [2022-03-16 18:53:18,219] {dag.py:2396} INFO - Sync 1 DAGs
[2022-03-16 18:53:18,248] {processor.py:171} INFO - Processing /opt/airflow/dags/gcs_ingestion_dag_NEWDATA.py took 0.707 seconds
[2022-03-16 18:53:49,071] {processor.py:163} INFO - Started process (PID=18437) to work on /opt/airflow/dags/gcs_ingestion_dag_NEWDATA.py
[2022-03-16 18:53:49,072] {processor.py:642} INFO - Processing file /opt/airflow/dags/gcs_ingestion_dag_NEWDATA.py for tasks to queue
[2022-03-16 18:53:49,073] {logging_mixin.py:109} INFO - [2022-03-16 18:53:49,072] {dagbag.py:500} INFO - Filling up the DagBag from /opt/airflow/dags/gcs_ingestion_dag_NEWDATA.py
[2022-03-16 18:53:49,536] {processor.py:654} INFO - DAG(s) dict_keys(['gcs_ingestion_dag_v02']) retrieved from /opt/airflow/dags/gcs_ingestion_dag_NEWDATA.py
[2022-03-16 18:53:49,541] {logging_mixin.py:109} INFO - [2022-03-16 18:53:49,541] {dag.py:2396} INFO - Sync 1 DAGs
[2022-03-16 18:53:49,557] {processor.py:171} INFO - Processing /opt/airflow/dags/gcs_ingestion_dag_NEWDATA.py took 0.488 seconds
[2022-03-16 18:54:20,398] {processor.py:163} INFO - Started process (PID=18552) to work on /opt/airflow/dags/gcs_ingestion_dag_NEWDATA.py
[2022-03-16 18:54:20,400] {processor.py:642} INFO - Processing file /opt/airflow/dags/gcs_ingestion_dag_NEWDATA.py for tasks to queue
[2022-03-16 18:54:20,400] {logging_mixin.py:109} INFO - [2022-03-16 18:54:20,400] {dagbag.py:500} INFO - Filling up the DagBag from /opt/airflow/dags/gcs_ingestion_dag_NEWDATA.py
[2022-03-16 18:54:20,876] {processor.py:654} INFO - DAG(s) dict_keys(['gcs_ingestion_dag_v02']) retrieved from /opt/airflow/dags/gcs_ingestion_dag_NEWDATA.py
[2022-03-16 18:54:20,879] {logging_mixin.py:109} INFO - [2022-03-16 18:54:20,878] {dag.py:2396} INFO - Sync 1 DAGs
[2022-03-16 18:54:20,894] {processor.py:171} INFO - Processing /opt/airflow/dags/gcs_ingestion_dag_NEWDATA.py took 0.498 seconds
[2022-03-16 18:54:51,589] {processor.py:163} INFO - Started process (PID=18668) to work on /opt/airflow/dags/gcs_ingestion_dag_NEWDATA.py
[2022-03-16 18:54:51,590] {processor.py:642} INFO - Processing file /opt/airflow/dags/gcs_ingestion_dag_NEWDATA.py for tasks to queue
[2022-03-16 18:54:51,591] {logging_mixin.py:109} INFO - [2022-03-16 18:54:51,591] {dagbag.py:500} INFO - Filling up the DagBag from /opt/airflow/dags/gcs_ingestion_dag_NEWDATA.py
[2022-03-16 18:54:52,044] {processor.py:654} INFO - DAG(s) dict_keys(['gcs_ingestion_dag_v02']) retrieved from /opt/airflow/dags/gcs_ingestion_dag_NEWDATA.py
[2022-03-16 18:54:52,178] {logging_mixin.py:109} INFO - [2022-03-16 18:54:52,178] {dag.py:2396} INFO - Sync 1 DAGs
[2022-03-16 18:54:52,202] {processor.py:171} INFO - Processing /opt/airflow/dags/gcs_ingestion_dag_NEWDATA.py took 0.616 seconds
[2022-03-16 18:55:22,778] {processor.py:163} INFO - Started process (PID=18775) to work on /opt/airflow/dags/gcs_ingestion_dag_NEWDATA.py
[2022-03-16 18:55:22,779] {processor.py:642} INFO - Processing file /opt/airflow/dags/gcs_ingestion_dag_NEWDATA.py for tasks to queue
[2022-03-16 18:55:22,780] {logging_mixin.py:109} INFO - [2022-03-16 18:55:22,780] {dagbag.py:500} INFO - Filling up the DagBag from /opt/airflow/dags/gcs_ingestion_dag_NEWDATA.py
[2022-03-16 18:55:23,238] {processor.py:654} INFO - DAG(s) dict_keys(['gcs_ingestion_dag_v02']) retrieved from /opt/airflow/dags/gcs_ingestion_dag_NEWDATA.py
[2022-03-16 18:55:23,244] {logging_mixin.py:109} INFO - [2022-03-16 18:55:23,244] {dag.py:2396} INFO - Sync 1 DAGs
[2022-03-16 18:55:23,259] {processor.py:171} INFO - Processing /opt/airflow/dags/gcs_ingestion_dag_NEWDATA.py took 0.483 seconds
[2022-03-16 18:55:53,295] {processor.py:163} INFO - Started process (PID=18892) to work on /opt/airflow/dags/gcs_ingestion_dag_NEWDATA.py
[2022-03-16 18:55:53,297] {processor.py:642} INFO - Processing file /opt/airflow/dags/gcs_ingestion_dag_NEWDATA.py for tasks to queue
[2022-03-16 18:55:53,297] {logging_mixin.py:109} INFO - [2022-03-16 18:55:53,297] {dagbag.py:500} INFO - Filling up the DagBag from /opt/airflow/dags/gcs_ingestion_dag_NEWDATA.py
[2022-03-16 18:55:53,798] {processor.py:654} INFO - DAG(s) dict_keys(['gcs_ingestion_dag_v02']) retrieved from /opt/airflow/dags/gcs_ingestion_dag_NEWDATA.py
[2022-03-16 18:55:53,800] {logging_mixin.py:109} INFO - [2022-03-16 18:55:53,800] {dag.py:2396} INFO - Sync 1 DAGs
[2022-03-16 18:55:53,816] {processor.py:171} INFO - Processing /opt/airflow/dags/gcs_ingestion_dag_NEWDATA.py took 0.523 seconds
[2022-03-16 18:56:24,174] {processor.py:163} INFO - Started process (PID=19007) to work on /opt/airflow/dags/gcs_ingestion_dag_NEWDATA.py
[2022-03-16 18:56:24,175] {processor.py:642} INFO - Processing file /opt/airflow/dags/gcs_ingestion_dag_NEWDATA.py for tasks to queue
[2022-03-16 18:56:24,176] {logging_mixin.py:109} INFO - [2022-03-16 18:56:24,176] {dagbag.py:500} INFO - Filling up the DagBag from /opt/airflow/dags/gcs_ingestion_dag_NEWDATA.py
[2022-03-16 18:56:24,668] {processor.py:654} INFO - DAG(s) dict_keys(['gcs_ingestion_dag_v02']) retrieved from /opt/airflow/dags/gcs_ingestion_dag_NEWDATA.py
[2022-03-16 18:56:24,826] {logging_mixin.py:109} INFO - [2022-03-16 18:56:24,826] {dag.py:2396} INFO - Sync 1 DAGs
[2022-03-16 18:56:24,844] {processor.py:171} INFO - Processing /opt/airflow/dags/gcs_ingestion_dag_NEWDATA.py took 0.672 seconds
[2022-03-16 18:56:55,655] {processor.py:163} INFO - Started process (PID=19112) to work on /opt/airflow/dags/gcs_ingestion_dag_NEWDATA.py
[2022-03-16 18:56:55,657] {processor.py:642} INFO - Processing file /opt/airflow/dags/gcs_ingestion_dag_NEWDATA.py for tasks to queue
[2022-03-16 18:56:55,657] {logging_mixin.py:109} INFO - [2022-03-16 18:56:55,657] {dagbag.py:500} INFO - Filling up the DagBag from /opt/airflow/dags/gcs_ingestion_dag_NEWDATA.py
[2022-03-16 18:56:56,131] {processor.py:654} INFO - DAG(s) dict_keys(['gcs_ingestion_dag_v02']) retrieved from /opt/airflow/dags/gcs_ingestion_dag_NEWDATA.py
[2022-03-16 18:56:56,137] {logging_mixin.py:109} INFO - [2022-03-16 18:56:56,137] {dag.py:2396} INFO - Sync 1 DAGs
[2022-03-16 18:56:56,152] {processor.py:171} INFO - Processing /opt/airflow/dags/gcs_ingestion_dag_NEWDATA.py took 0.498 seconds
[2022-03-16 18:57:26,554] {processor.py:163} INFO - Started process (PID=19227) to work on /opt/airflow/dags/gcs_ingestion_dag_NEWDATA.py
[2022-03-16 18:57:26,555] {processor.py:642} INFO - Processing file /opt/airflow/dags/gcs_ingestion_dag_NEWDATA.py for tasks to queue
[2022-03-16 18:57:26,555] {logging_mixin.py:109} INFO - [2022-03-16 18:57:26,555] {dagbag.py:500} INFO - Filling up the DagBag from /opt/airflow/dags/gcs_ingestion_dag_NEWDATA.py
[2022-03-16 18:57:27,024] {processor.py:654} INFO - DAG(s) dict_keys(['gcs_ingestion_dag_v02']) retrieved from /opt/airflow/dags/gcs_ingestion_dag_NEWDATA.py
[2022-03-16 18:57:27,026] {logging_mixin.py:109} INFO - [2022-03-16 18:57:27,026] {dag.py:2396} INFO - Sync 1 DAGs
[2022-03-16 18:57:27,041] {processor.py:171} INFO - Processing /opt/airflow/dags/gcs_ingestion_dag_NEWDATA.py took 0.490 seconds
[2022-03-16 18:57:57,404] {processor.py:163} INFO - Started process (PID=19342) to work on /opt/airflow/dags/gcs_ingestion_dag_NEWDATA.py
[2022-03-16 18:57:57,412] {processor.py:642} INFO - Processing file /opt/airflow/dags/gcs_ingestion_dag_NEWDATA.py for tasks to queue
[2022-03-16 18:57:57,413] {logging_mixin.py:109} INFO - [2022-03-16 18:57:57,413] {dagbag.py:500} INFO - Filling up the DagBag from /opt/airflow/dags/gcs_ingestion_dag_NEWDATA.py
[2022-03-16 18:57:57,876] {processor.py:654} INFO - DAG(s) dict_keys(['gcs_ingestion_dag_v02']) retrieved from /opt/airflow/dags/gcs_ingestion_dag_NEWDATA.py
[2022-03-16 18:57:58,009] {logging_mixin.py:109} INFO - [2022-03-16 18:57:58,009] {dag.py:2396} INFO - Sync 1 DAGs
[2022-03-16 18:57:58,026] {processor.py:171} INFO - Processing /opt/airflow/dags/gcs_ingestion_dag_NEWDATA.py took 0.624 seconds
[2022-03-16 18:58:03,242] {processor.py:163} INFO - Started process (PID=19376) to work on /opt/airflow/dags/gcs_ingestion_dag_NEWDATA.py
[2022-03-16 18:58:03,243] {processor.py:642} INFO - Processing file /opt/airflow/dags/gcs_ingestion_dag_NEWDATA.py for tasks to queue
[2022-03-16 18:58:03,243] {logging_mixin.py:109} INFO - [2022-03-16 18:58:03,243] {dagbag.py:500} INFO - Filling up the DagBag from /opt/airflow/dags/gcs_ingestion_dag_NEWDATA.py
[2022-03-16 18:58:03,703] {logging_mixin.py:109} INFO - [2022-03-16 18:58:03,703] {dagbag.py:334} ERROR - Failed to import: /opt/airflow/dags/gcs_ingestion_dag_NEWDATA.py
Traceback (most recent call last):
  File "/home/airflow/.local/lib/python3.7/site-packages/airflow/models/dagbag.py", line 331, in _load_modules_from_file
    loader.exec_module(new_module)
  File "<frozen importlib._bootstrap_external>", line 728, in exec_module
  File "<frozen importlib._bootstrap>", line 219, in _call_with_frames_removed
  File "/opt/airflow/dags/gcs_ingestion_dag_NEWDATA.py", line 79, in <module>
    bash_command=f"curl -sSLf {dataset_url} > {path_to_local_home}/{dataset_archive}"
NameError: name 'dataset_url' is not defined
[2022-03-16 18:58:03,711] {processor.py:690} INFO - Deactivated 1 DAGs which are no longer present in /opt/airflow/dags/gcs_ingestion_dag_NEWDATA.py
[2022-03-16 18:58:03,711] {processor.py:656} WARNING - No viable dags retrieved from /opt/airflow/dags/gcs_ingestion_dag_NEWDATA.py
[2022-03-16 18:58:03,717] {processor.py:171} INFO - Processing /opt/airflow/dags/gcs_ingestion_dag_NEWDATA.py took 0.477 seconds
[2022-03-16 18:58:33,938] {processor.py:163} INFO - Started process (PID=19491) to work on /opt/airflow/dags/gcs_ingestion_dag_NEWDATA.py
[2022-03-16 18:58:33,940] {processor.py:642} INFO - Processing file /opt/airflow/dags/gcs_ingestion_dag_NEWDATA.py for tasks to queue
[2022-03-16 18:58:33,940] {logging_mixin.py:109} INFO - [2022-03-16 18:58:33,940] {dagbag.py:500} INFO - Filling up the DagBag from /opt/airflow/dags/gcs_ingestion_dag_NEWDATA.py
[2022-03-16 18:58:34,397] {logging_mixin.py:109} INFO - [2022-03-16 18:58:34,396] {dagbag.py:334} ERROR - Failed to import: /opt/airflow/dags/gcs_ingestion_dag_NEWDATA.py
Traceback (most recent call last):
  File "/home/airflow/.local/lib/python3.7/site-packages/airflow/models/dagbag.py", line 331, in _load_modules_from_file
    loader.exec_module(new_module)
  File "<frozen importlib._bootstrap_external>", line 728, in exec_module
  File "<frozen importlib._bootstrap>", line 219, in _call_with_frames_removed
  File "/opt/airflow/dags/gcs_ingestion_dag_NEWDATA.py", line 79, in <module>
    bash_command=f"curl -sSLf {dataset_url} > {path_to_local_home}/{dataset_archive}"
NameError: name 'dataset_url' is not defined
[2022-03-16 18:58:34,404] {processor.py:656} WARNING - No viable dags retrieved from /opt/airflow/dags/gcs_ingestion_dag_NEWDATA.py
[2022-03-16 18:58:34,410] {processor.py:171} INFO - Processing /opt/airflow/dags/gcs_ingestion_dag_NEWDATA.py took 0.474 seconds
[2022-03-16 18:59:05,096] {processor.py:163} INFO - Started process (PID=19603) to work on /opt/airflow/dags/gcs_ingestion_dag_NEWDATA.py
[2022-03-16 18:59:05,098] {processor.py:642} INFO - Processing file /opt/airflow/dags/gcs_ingestion_dag_NEWDATA.py for tasks to queue
[2022-03-16 18:59:05,098] {logging_mixin.py:109} INFO - [2022-03-16 18:59:05,098] {dagbag.py:500} INFO - Filling up the DagBag from /opt/airflow/dags/gcs_ingestion_dag_NEWDATA.py
[2022-03-16 18:59:05,596] {logging_mixin.py:109} INFO - [2022-03-16 18:59:05,596] {dagbag.py:334} ERROR - Failed to import: /opt/airflow/dags/gcs_ingestion_dag_NEWDATA.py
Traceback (most recent call last):
  File "/home/airflow/.local/lib/python3.7/site-packages/airflow/models/dagbag.py", line 331, in _load_modules_from_file
    loader.exec_module(new_module)
  File "<frozen importlib._bootstrap_external>", line 728, in exec_module
  File "<frozen importlib._bootstrap>", line 219, in _call_with_frames_removed
  File "/opt/airflow/dags/gcs_ingestion_dag_NEWDATA.py", line 79, in <module>
    bash_command=f"curl -sSLf {dataset_url} > {path_to_local_home}/{dataset_archive}"
NameError: name 'dataset_url' is not defined
[2022-03-16 18:59:05,605] {processor.py:656} WARNING - No viable dags retrieved from /opt/airflow/dags/gcs_ingestion_dag_NEWDATA.py
[2022-03-16 18:59:05,610] {processor.py:171} INFO - Processing /opt/airflow/dags/gcs_ingestion_dag_NEWDATA.py took 0.516 seconds
[2022-03-16 18:59:36,317] {processor.py:163} INFO - Started process (PID=19710) to work on /opt/airflow/dags/gcs_ingestion_dag_NEWDATA.py
[2022-03-16 18:59:36,319] {processor.py:642} INFO - Processing file /opt/airflow/dags/gcs_ingestion_dag_NEWDATA.py for tasks to queue
[2022-03-16 18:59:36,319] {logging_mixin.py:109} INFO - [2022-03-16 18:59:36,319] {dagbag.py:500} INFO - Filling up the DagBag from /opt/airflow/dags/gcs_ingestion_dag_NEWDATA.py
[2022-03-16 18:59:36,777] {logging_mixin.py:109} INFO - [2022-03-16 18:59:36,777] {dagbag.py:334} ERROR - Failed to import: /opt/airflow/dags/gcs_ingestion_dag_NEWDATA.py
Traceback (most recent call last):
  File "/home/airflow/.local/lib/python3.7/site-packages/airflow/models/dagbag.py", line 331, in _load_modules_from_file
    loader.exec_module(new_module)
  File "<frozen importlib._bootstrap_external>", line 728, in exec_module
  File "<frozen importlib._bootstrap>", line 219, in _call_with_frames_removed
  File "/opt/airflow/dags/gcs_ingestion_dag_NEWDATA.py", line 79, in <module>
    bash_command=f"curl -sSLf {dataset_url} > {path_to_local_home}/{dataset_archive}"
NameError: name 'dataset_url' is not defined
[2022-03-16 18:59:36,785] {processor.py:656} WARNING - No viable dags retrieved from /opt/airflow/dags/gcs_ingestion_dag_NEWDATA.py
[2022-03-16 18:59:36,790] {processor.py:171} INFO - Processing /opt/airflow/dags/gcs_ingestion_dag_NEWDATA.py took 0.475 seconds
[2022-03-16 19:00:07,500] {processor.py:163} INFO - Started process (PID=19825) to work on /opt/airflow/dags/gcs_ingestion_dag_NEWDATA.py
[2022-03-16 19:00:07,501] {processor.py:642} INFO - Processing file /opt/airflow/dags/gcs_ingestion_dag_NEWDATA.py for tasks to queue
[2022-03-16 19:00:07,502] {logging_mixin.py:109} INFO - [2022-03-16 19:00:07,502] {dagbag.py:500} INFO - Filling up the DagBag from /opt/airflow/dags/gcs_ingestion_dag_NEWDATA.py
[2022-03-16 19:00:07,956] {logging_mixin.py:109} INFO - [2022-03-16 19:00:07,955] {dagbag.py:334} ERROR - Failed to import: /opt/airflow/dags/gcs_ingestion_dag_NEWDATA.py
Traceback (most recent call last):
  File "/home/airflow/.local/lib/python3.7/site-packages/airflow/models/dagbag.py", line 331, in _load_modules_from_file
    loader.exec_module(new_module)
  File "<frozen importlib._bootstrap_external>", line 728, in exec_module
  File "<frozen importlib._bootstrap>", line 219, in _call_with_frames_removed
  File "/opt/airflow/dags/gcs_ingestion_dag_NEWDATA.py", line 79, in <module>
    bash_command=f"curl -sSLf {dataset_url} > {path_to_local_home}/{dataset_archive}"
NameError: name 'dataset_url' is not defined
[2022-03-16 19:00:07,964] {processor.py:656} WARNING - No viable dags retrieved from /opt/airflow/dags/gcs_ingestion_dag_NEWDATA.py
[2022-03-16 19:00:07,969] {processor.py:171} INFO - Processing /opt/airflow/dags/gcs_ingestion_dag_NEWDATA.py took 0.471 seconds
[2022-03-16 19:00:38,022] {processor.py:163} INFO - Started process (PID=19934) to work on /opt/airflow/dags/gcs_ingestion_dag_NEWDATA.py
[2022-03-16 19:00:38,024] {processor.py:642} INFO - Processing file /opt/airflow/dags/gcs_ingestion_dag_NEWDATA.py for tasks to queue
[2022-03-16 19:00:38,024] {logging_mixin.py:109} INFO - [2022-03-16 19:00:38,024] {dagbag.py:500} INFO - Filling up the DagBag from /opt/airflow/dags/gcs_ingestion_dag_NEWDATA.py
[2022-03-16 19:00:38,521] {logging_mixin.py:109} INFO - [2022-03-16 19:00:38,520] {dagbag.py:334} ERROR - Failed to import: /opt/airflow/dags/gcs_ingestion_dag_NEWDATA.py
Traceback (most recent call last):
  File "/home/airflow/.local/lib/python3.7/site-packages/airflow/models/dagbag.py", line 331, in _load_modules_from_file
    loader.exec_module(new_module)
  File "<frozen importlib._bootstrap_external>", line 728, in exec_module
  File "<frozen importlib._bootstrap>", line 219, in _call_with_frames_removed
  File "/opt/airflow/dags/gcs_ingestion_dag_NEWDATA.py", line 79, in <module>
    bash_command=f"curl -sSLf {dataset_url} > {path_to_local_home}/{dataset_archive}"
NameError: name 'dataset_url' is not defined
[2022-03-16 19:00:38,529] {processor.py:656} WARNING - No viable dags retrieved from /opt/airflow/dags/gcs_ingestion_dag_NEWDATA.py
[2022-03-16 19:00:38,534] {processor.py:171} INFO - Processing /opt/airflow/dags/gcs_ingestion_dag_NEWDATA.py took 0.514 seconds
[2022-03-16 19:01:09,224] {processor.py:163} INFO - Started process (PID=20048) to work on /opt/airflow/dags/gcs_ingestion_dag_NEWDATA.py
[2022-03-16 19:01:09,233] {processor.py:642} INFO - Processing file /opt/airflow/dags/gcs_ingestion_dag_NEWDATA.py for tasks to queue
[2022-03-16 19:01:09,233] {logging_mixin.py:109} INFO - [2022-03-16 19:01:09,233] {dagbag.py:500} INFO - Filling up the DagBag from /opt/airflow/dags/gcs_ingestion_dag_NEWDATA.py
[2022-03-16 19:01:09,694] {logging_mixin.py:109} INFO - [2022-03-16 19:01:09,694] {dagbag.py:334} ERROR - Failed to import: /opt/airflow/dags/gcs_ingestion_dag_NEWDATA.py
Traceback (most recent call last):
  File "/home/airflow/.local/lib/python3.7/site-packages/airflow/models/dagbag.py", line 331, in _load_modules_from_file
    loader.exec_module(new_module)
  File "<frozen importlib._bootstrap_external>", line 728, in exec_module
  File "<frozen importlib._bootstrap>", line 219, in _call_with_frames_removed
  File "/opt/airflow/dags/gcs_ingestion_dag_NEWDATA.py", line 79, in <module>
    bash_command=f"curl -sSLf {dataset_url} > {path_to_local_home}/{dataset_archive}"
NameError: name 'dataset_url' is not defined
[2022-03-16 19:01:09,702] {processor.py:656} WARNING - No viable dags retrieved from /opt/airflow/dags/gcs_ingestion_dag_NEWDATA.py
[2022-03-16 19:01:09,707] {processor.py:171} INFO - Processing /opt/airflow/dags/gcs_ingestion_dag_NEWDATA.py took 0.485 seconds
[2022-03-16 19:01:39,810] {processor.py:163} INFO - Started process (PID=20162) to work on /opt/airflow/dags/gcs_ingestion_dag_NEWDATA.py
[2022-03-16 19:01:39,812] {processor.py:642} INFO - Processing file /opt/airflow/dags/gcs_ingestion_dag_NEWDATA.py for tasks to queue
[2022-03-16 19:01:39,812] {logging_mixin.py:109} INFO - [2022-03-16 19:01:39,812] {dagbag.py:500} INFO - Filling up the DagBag from /opt/airflow/dags/gcs_ingestion_dag_NEWDATA.py
[2022-03-16 19:01:40,289] {logging_mixin.py:109} INFO - [2022-03-16 19:01:40,289] {dagbag.py:334} ERROR - Failed to import: /opt/airflow/dags/gcs_ingestion_dag_NEWDATA.py
Traceback (most recent call last):
  File "/home/airflow/.local/lib/python3.7/site-packages/airflow/models/dagbag.py", line 331, in _load_modules_from_file
    loader.exec_module(new_module)
  File "<frozen importlib._bootstrap_external>", line 728, in exec_module
  File "<frozen importlib._bootstrap>", line 219, in _call_with_frames_removed
  File "/opt/airflow/dags/gcs_ingestion_dag_NEWDATA.py", line 79, in <module>
    bash_command=f"curl -sSLf {dataset_url} > {path_to_local_home}/{dataset_archive}"
NameError: name 'dataset_url' is not defined
[2022-03-16 19:01:40,297] {processor.py:656} WARNING - No viable dags retrieved from /opt/airflow/dags/gcs_ingestion_dag_NEWDATA.py
[2022-03-16 19:01:40,303] {processor.py:171} INFO - Processing /opt/airflow/dags/gcs_ingestion_dag_NEWDATA.py took 0.495 seconds
[2022-03-16 19:02:11,015] {processor.py:163} INFO - Started process (PID=20269) to work on /opt/airflow/dags/gcs_ingestion_dag_NEWDATA.py
[2022-03-16 19:02:11,016] {processor.py:642} INFO - Processing file /opt/airflow/dags/gcs_ingestion_dag_NEWDATA.py for tasks to queue
[2022-03-16 19:02:11,016] {logging_mixin.py:109} INFO - [2022-03-16 19:02:11,016] {dagbag.py:500} INFO - Filling up the DagBag from /opt/airflow/dags/gcs_ingestion_dag_NEWDATA.py
[2022-03-16 19:02:11,535] {logging_mixin.py:109} INFO - [2022-03-16 19:02:11,534] {dagbag.py:334} ERROR - Failed to import: /opt/airflow/dags/gcs_ingestion_dag_NEWDATA.py
Traceback (most recent call last):
  File "/home/airflow/.local/lib/python3.7/site-packages/airflow/models/dagbag.py", line 331, in _load_modules_from_file
    loader.exec_module(new_module)
  File "<frozen importlib._bootstrap_external>", line 728, in exec_module
  File "<frozen importlib._bootstrap>", line 219, in _call_with_frames_removed
  File "/opt/airflow/dags/gcs_ingestion_dag_NEWDATA.py", line 79, in <module>
    bash_command=f"curl -sSLf {dataset_url} > {path_to_local_home}/{dataset_archive}"
NameError: name 'dataset_url' is not defined
[2022-03-16 19:02:11,542] {processor.py:656} WARNING - No viable dags retrieved from /opt/airflow/dags/gcs_ingestion_dag_NEWDATA.py
[2022-03-16 19:02:11,548] {processor.py:171} INFO - Processing /opt/airflow/dags/gcs_ingestion_dag_NEWDATA.py took 0.534 seconds
[2022-03-16 19:02:42,225] {processor.py:163} INFO - Started process (PID=20384) to work on /opt/airflow/dags/gcs_ingestion_dag_NEWDATA.py
[2022-03-16 19:02:42,226] {processor.py:642} INFO - Processing file /opt/airflow/dags/gcs_ingestion_dag_NEWDATA.py for tasks to queue
[2022-03-16 19:02:42,226] {logging_mixin.py:109} INFO - [2022-03-16 19:02:42,226] {dagbag.py:500} INFO - Filling up the DagBag from /opt/airflow/dags/gcs_ingestion_dag_NEWDATA.py
[2022-03-16 19:02:42,692] {logging_mixin.py:109} INFO - [2022-03-16 19:02:42,692] {dagbag.py:334} ERROR - Failed to import: /opt/airflow/dags/gcs_ingestion_dag_NEWDATA.py
Traceback (most recent call last):
  File "/home/airflow/.local/lib/python3.7/site-packages/airflow/models/dagbag.py", line 331, in _load_modules_from_file
    loader.exec_module(new_module)
  File "<frozen importlib._bootstrap_external>", line 728, in exec_module
  File "<frozen importlib._bootstrap>", line 219, in _call_with_frames_removed
  File "/opt/airflow/dags/gcs_ingestion_dag_NEWDATA.py", line 79, in <module>
    bash_command=f"curl -sSLf {dataset_url} > {path_to_local_home}/{dataset_archive}"
NameError: name 'dataset_url' is not defined
[2022-03-16 19:02:42,700] {processor.py:656} WARNING - No viable dags retrieved from /opt/airflow/dags/gcs_ingestion_dag_NEWDATA.py
[2022-03-16 19:02:42,706] {processor.py:171} INFO - Processing /opt/airflow/dags/gcs_ingestion_dag_NEWDATA.py took 0.483 seconds
[2022-03-16 19:03:12,777] {processor.py:163} INFO - Started process (PID=20500) to work on /opt/airflow/dags/gcs_ingestion_dag_NEWDATA.py
[2022-03-16 19:03:12,779] {processor.py:642} INFO - Processing file /opt/airflow/dags/gcs_ingestion_dag_NEWDATA.py for tasks to queue
[2022-03-16 19:03:12,779] {logging_mixin.py:109} INFO - [2022-03-16 19:03:12,779] {dagbag.py:500} INFO - Filling up the DagBag from /opt/airflow/dags/gcs_ingestion_dag_NEWDATA.py
[2022-03-16 19:03:13,231] {logging_mixin.py:109} INFO - [2022-03-16 19:03:13,231] {dagbag.py:334} ERROR - Failed to import: /opt/airflow/dags/gcs_ingestion_dag_NEWDATA.py
Traceback (most recent call last):
  File "/home/airflow/.local/lib/python3.7/site-packages/airflow/models/dagbag.py", line 331, in _load_modules_from_file
    loader.exec_module(new_module)
  File "<frozen importlib._bootstrap_external>", line 728, in exec_module
  File "<frozen importlib._bootstrap>", line 219, in _call_with_frames_removed
  File "/opt/airflow/dags/gcs_ingestion_dag_NEWDATA.py", line 79, in <module>
    bash_command=f"curl -sSLf {dataset_url} > {path_to_local_home}/{dataset_archive}"
NameError: name 'dataset_url' is not defined
[2022-03-16 19:03:13,239] {processor.py:656} WARNING - No viable dags retrieved from /opt/airflow/dags/gcs_ingestion_dag_NEWDATA.py
[2022-03-16 19:03:13,245] {processor.py:171} INFO - Processing /opt/airflow/dags/gcs_ingestion_dag_NEWDATA.py took 0.470 seconds
[2022-03-16 19:03:43,956] {processor.py:163} INFO - Started process (PID=20605) to work on /opt/airflow/dags/gcs_ingestion_dag_NEWDATA.py
[2022-03-16 19:03:43,964] {processor.py:642} INFO - Processing file /opt/airflow/dags/gcs_ingestion_dag_NEWDATA.py for tasks to queue
[2022-03-16 19:03:43,965] {logging_mixin.py:109} INFO - [2022-03-16 19:03:43,965] {dagbag.py:500} INFO - Filling up the DagBag from /opt/airflow/dags/gcs_ingestion_dag_NEWDATA.py
[2022-03-16 19:03:44,453] {logging_mixin.py:109} INFO - [2022-03-16 19:03:44,452] {dagbag.py:334} ERROR - Failed to import: /opt/airflow/dags/gcs_ingestion_dag_NEWDATA.py
Traceback (most recent call last):
  File "/home/airflow/.local/lib/python3.7/site-packages/airflow/models/dagbag.py", line 331, in _load_modules_from_file
    loader.exec_module(new_module)
  File "<frozen importlib._bootstrap_external>", line 728, in exec_module
  File "<frozen importlib._bootstrap>", line 219, in _call_with_frames_removed
  File "/opt/airflow/dags/gcs_ingestion_dag_NEWDATA.py", line 79, in <module>
    bash_command=f"curl -sSLf {dataset_url} > {path_to_local_home}/{dataset_archive}"
NameError: name 'dataset_url' is not defined
[2022-03-16 19:03:44,460] {processor.py:656} WARNING - No viable dags retrieved from /opt/airflow/dags/gcs_ingestion_dag_NEWDATA.py
[2022-03-16 19:03:44,466] {processor.py:171} INFO - Processing /opt/airflow/dags/gcs_ingestion_dag_NEWDATA.py took 0.512 seconds
[2022-03-16 19:04:14,521] {processor.py:163} INFO - Started process (PID=20719) to work on /opt/airflow/dags/gcs_ingestion_dag_NEWDATA.py
[2022-03-16 19:04:14,522] {processor.py:642} INFO - Processing file /opt/airflow/dags/gcs_ingestion_dag_NEWDATA.py for tasks to queue
[2022-03-16 19:04:14,522] {logging_mixin.py:109} INFO - [2022-03-16 19:04:14,522] {dagbag.py:500} INFO - Filling up the DagBag from /opt/airflow/dags/gcs_ingestion_dag_NEWDATA.py
[2022-03-16 19:04:14,993] {logging_mixin.py:109} INFO - [2022-03-16 19:04:14,993] {dagbag.py:334} ERROR - Failed to import: /opt/airflow/dags/gcs_ingestion_dag_NEWDATA.py
Traceback (most recent call last):
  File "/home/airflow/.local/lib/python3.7/site-packages/airflow/models/dagbag.py", line 331, in _load_modules_from_file
    loader.exec_module(new_module)
  File "<frozen importlib._bootstrap_external>", line 728, in exec_module
  File "<frozen importlib._bootstrap>", line 219, in _call_with_frames_removed
  File "/opt/airflow/dags/gcs_ingestion_dag_NEWDATA.py", line 79, in <module>
    bash_command=f"curl -sSLf {dataset_url} > {path_to_local_home}/{dataset_archive}"
NameError: name 'dataset_url' is not defined
[2022-03-16 19:04:15,001] {processor.py:656} WARNING - No viable dags retrieved from /opt/airflow/dags/gcs_ingestion_dag_NEWDATA.py
[2022-03-16 19:04:15,007] {processor.py:171} INFO - Processing /opt/airflow/dags/gcs_ingestion_dag_NEWDATA.py took 0.488 seconds
[2022-03-16 19:04:45,871] {processor.py:163} INFO - Started process (PID=20833) to work on /opt/airflow/dags/gcs_ingestion_dag_NEWDATA.py
[2022-03-16 19:04:45,879] {processor.py:642} INFO - Processing file /opt/airflow/dags/gcs_ingestion_dag_NEWDATA.py for tasks to queue
[2022-03-16 19:04:45,880] {logging_mixin.py:109} INFO - [2022-03-16 19:04:45,880] {dagbag.py:500} INFO - Filling up the DagBag from /opt/airflow/dags/gcs_ingestion_dag_NEWDATA.py
[2022-03-16 19:04:46,321] {logging_mixin.py:109} INFO - [2022-03-16 19:04:46,320] {dagbag.py:334} ERROR - Failed to import: /opt/airflow/dags/gcs_ingestion_dag_NEWDATA.py
Traceback (most recent call last):
  File "/home/airflow/.local/lib/python3.7/site-packages/airflow/models/dagbag.py", line 331, in _load_modules_from_file
    loader.exec_module(new_module)
  File "<frozen importlib._bootstrap_external>", line 728, in exec_module
  File "<frozen importlib._bootstrap>", line 219, in _call_with_frames_removed
  File "/opt/airflow/dags/gcs_ingestion_dag_NEWDATA.py", line 79, in <module>
    bash_command=f"curl -sSLf {dataset_url} > {path_to_local_home}/{dataset_archive}"
NameError: name 'dataset_url' is not defined
[2022-03-16 19:04:46,328] {processor.py:656} WARNING - No viable dags retrieved from /opt/airflow/dags/gcs_ingestion_dag_NEWDATA.py
[2022-03-16 19:04:46,337] {processor.py:171} INFO - Processing /opt/airflow/dags/gcs_ingestion_dag_NEWDATA.py took 0.469 seconds
[2022-03-16 19:05:16,389] {processor.py:163} INFO - Started process (PID=20939) to work on /opt/airflow/dags/gcs_ingestion_dag_NEWDATA.py
[2022-03-16 19:05:16,390] {processor.py:642} INFO - Processing file /opt/airflow/dags/gcs_ingestion_dag_NEWDATA.py for tasks to queue
[2022-03-16 19:05:16,391] {logging_mixin.py:109} INFO - [2022-03-16 19:05:16,391] {dagbag.py:500} INFO - Filling up the DagBag from /opt/airflow/dags/gcs_ingestion_dag_NEWDATA.py
[2022-03-16 19:05:16,926] {logging_mixin.py:109} INFO - [2022-03-16 19:05:16,925] {dagbag.py:334} ERROR - Failed to import: /opt/airflow/dags/gcs_ingestion_dag_NEWDATA.py
Traceback (most recent call last):
  File "/home/airflow/.local/lib/python3.7/site-packages/airflow/models/dagbag.py", line 331, in _load_modules_from_file
    loader.exec_module(new_module)
  File "<frozen importlib._bootstrap_external>", line 728, in exec_module
  File "<frozen importlib._bootstrap>", line 219, in _call_with_frames_removed
  File "/opt/airflow/dags/gcs_ingestion_dag_NEWDATA.py", line 79, in <module>
    bash_command=f"curl -sSLf {dataset_url} > {path_to_local_home}/{dataset_archive}"
NameError: name 'dataset_url' is not defined
[2022-03-16 19:05:16,936] {processor.py:656} WARNING - No viable dags retrieved from /opt/airflow/dags/gcs_ingestion_dag_NEWDATA.py
[2022-03-16 19:05:16,941] {processor.py:171} INFO - Processing /opt/airflow/dags/gcs_ingestion_dag_NEWDATA.py took 0.554 seconds
[2022-03-16 19:05:47,769] {processor.py:163} INFO - Started process (PID=21054) to work on /opt/airflow/dags/gcs_ingestion_dag_NEWDATA.py
[2022-03-16 19:05:47,770] {processor.py:642} INFO - Processing file /opt/airflow/dags/gcs_ingestion_dag_NEWDATA.py for tasks to queue
[2022-03-16 19:05:47,770] {logging_mixin.py:109} INFO - [2022-03-16 19:05:47,770] {dagbag.py:500} INFO - Filling up the DagBag from /opt/airflow/dags/gcs_ingestion_dag_NEWDATA.py
[2022-03-16 19:05:48,266] {logging_mixin.py:109} INFO - [2022-03-16 19:05:48,265] {dagbag.py:334} ERROR - Failed to import: /opt/airflow/dags/gcs_ingestion_dag_NEWDATA.py
Traceback (most recent call last):
  File "/home/airflow/.local/lib/python3.7/site-packages/airflow/models/dagbag.py", line 331, in _load_modules_from_file
    loader.exec_module(new_module)
  File "<frozen importlib._bootstrap_external>", line 728, in exec_module
  File "<frozen importlib._bootstrap>", line 219, in _call_with_frames_removed
  File "/opt/airflow/dags/gcs_ingestion_dag_NEWDATA.py", line 79, in <module>
    bash_command=f"curl -sSLf {dataset_url} > {path_to_local_home}/{dataset_archive}"
NameError: name 'dataset_url' is not defined
[2022-03-16 19:05:48,274] {processor.py:656} WARNING - No viable dags retrieved from /opt/airflow/dags/gcs_ingestion_dag_NEWDATA.py
[2022-03-16 19:05:48,279] {processor.py:171} INFO - Processing /opt/airflow/dags/gcs_ingestion_dag_NEWDATA.py took 0.512 seconds
[2022-03-16 19:06:18,301] {processor.py:163} INFO - Started process (PID=21187) to work on /opt/airflow/dags/gcs_ingestion_dag_NEWDATA.py
[2022-03-16 19:06:18,302] {processor.py:642} INFO - Processing file /opt/airflow/dags/gcs_ingestion_dag_NEWDATA.py for tasks to queue
[2022-03-16 19:06:18,302] {logging_mixin.py:109} INFO - [2022-03-16 19:06:18,302] {dagbag.py:500} INFO - Filling up the DagBag from /opt/airflow/dags/gcs_ingestion_dag_NEWDATA.py
[2022-03-16 19:06:18,750] {logging_mixin.py:109} INFO - [2022-03-16 19:06:18,750] {dagbag.py:334} ERROR - Failed to import: /opt/airflow/dags/gcs_ingestion_dag_NEWDATA.py
Traceback (most recent call last):
  File "/home/airflow/.local/lib/python3.7/site-packages/airflow/models/dagbag.py", line 331, in _load_modules_from_file
    loader.exec_module(new_module)
  File "<frozen importlib._bootstrap_external>", line 728, in exec_module
  File "<frozen importlib._bootstrap>", line 219, in _call_with_frames_removed
  File "/opt/airflow/dags/gcs_ingestion_dag_NEWDATA.py", line 79, in <module>
    bash_command=f"curl -sSLf {dataset_url} > {path_to_local_home}/{dataset_archive}"
NameError: name 'dataset_url' is not defined
[2022-03-16 19:06:18,758] {processor.py:656} WARNING - No viable dags retrieved from /opt/airflow/dags/gcs_ingestion_dag_NEWDATA.py
[2022-03-16 19:06:18,764] {processor.py:171} INFO - Processing /opt/airflow/dags/gcs_ingestion_dag_NEWDATA.py took 0.464 seconds
[2022-03-16 19:06:49,635] {processor.py:163} INFO - Started process (PID=21292) to work on /opt/airflow/dags/gcs_ingestion_dag_NEWDATA.py
[2022-03-16 19:06:49,636] {processor.py:642} INFO - Processing file /opt/airflow/dags/gcs_ingestion_dag_NEWDATA.py for tasks to queue
[2022-03-16 19:06:49,636] {logging_mixin.py:109} INFO - [2022-03-16 19:06:49,636] {dagbag.py:500} INFO - Filling up the DagBag from /opt/airflow/dags/gcs_ingestion_dag_NEWDATA.py
[2022-03-16 19:06:50,089] {logging_mixin.py:109} INFO - [2022-03-16 19:06:50,089] {dagbag.py:334} ERROR - Failed to import: /opt/airflow/dags/gcs_ingestion_dag_NEWDATA.py
Traceback (most recent call last):
  File "/home/airflow/.local/lib/python3.7/site-packages/airflow/models/dagbag.py", line 331, in _load_modules_from_file
    loader.exec_module(new_module)
  File "<frozen importlib._bootstrap_external>", line 728, in exec_module
  File "<frozen importlib._bootstrap>", line 219, in _call_with_frames_removed
  File "/opt/airflow/dags/gcs_ingestion_dag_NEWDATA.py", line 79, in <module>
    bash_command=f"curl -sSLf {dataset_url} > {path_to_local_home}/{dataset_archive}"
NameError: name 'dataset_url' is not defined
[2022-03-16 19:06:50,097] {processor.py:656} WARNING - No viable dags retrieved from /opt/airflow/dags/gcs_ingestion_dag_NEWDATA.py
[2022-03-16 19:06:50,102] {processor.py:171} INFO - Processing /opt/airflow/dags/gcs_ingestion_dag_NEWDATA.py took 0.470 seconds
[2022-03-16 19:07:20,933] {processor.py:163} INFO - Started process (PID=21407) to work on /opt/airflow/dags/gcs_ingestion_dag_NEWDATA.py
[2022-03-16 19:07:20,941] {processor.py:642} INFO - Processing file /opt/airflow/dags/gcs_ingestion_dag_NEWDATA.py for tasks to queue
[2022-03-16 19:07:20,942] {logging_mixin.py:109} INFO - [2022-03-16 19:07:20,942] {dagbag.py:500} INFO - Filling up the DagBag from /opt/airflow/dags/gcs_ingestion_dag_NEWDATA.py
[2022-03-16 19:07:21,396] {logging_mixin.py:109} INFO - [2022-03-16 19:07:21,396] {dagbag.py:334} ERROR - Failed to import: /opt/airflow/dags/gcs_ingestion_dag_NEWDATA.py
Traceback (most recent call last):
  File "/home/airflow/.local/lib/python3.7/site-packages/airflow/models/dagbag.py", line 331, in _load_modules_from_file
    loader.exec_module(new_module)
  File "<frozen importlib._bootstrap_external>", line 728, in exec_module
  File "<frozen importlib._bootstrap>", line 219, in _call_with_frames_removed
  File "/opt/airflow/dags/gcs_ingestion_dag_NEWDATA.py", line 79, in <module>
    bash_command=f"curl -sSLf {dataset_url} > {path_to_local_home}/{dataset_archive}"
NameError: name 'dataset_url' is not defined
[2022-03-16 19:07:21,404] {processor.py:656} WARNING - No viable dags retrieved from /opt/airflow/dags/gcs_ingestion_dag_NEWDATA.py
[2022-03-16 19:07:21,410] {processor.py:171} INFO - Processing /opt/airflow/dags/gcs_ingestion_dag_NEWDATA.py took 0.479 seconds
[2022-03-16 19:07:52,250] {processor.py:163} INFO - Started process (PID=21521) to work on /opt/airflow/dags/gcs_ingestion_dag_NEWDATA.py
[2022-03-16 19:07:52,251] {processor.py:642} INFO - Processing file /opt/airflow/dags/gcs_ingestion_dag_NEWDATA.py for tasks to queue
[2022-03-16 19:07:52,251] {logging_mixin.py:109} INFO - [2022-03-16 19:07:52,251] {dagbag.py:500} INFO - Filling up the DagBag from /opt/airflow/dags/gcs_ingestion_dag_NEWDATA.py
[2022-03-16 19:07:52,723] {logging_mixin.py:109} INFO - [2022-03-16 19:07:52,723] {dagbag.py:334} ERROR - Failed to import: /opt/airflow/dags/gcs_ingestion_dag_NEWDATA.py
Traceback (most recent call last):
  File "/home/airflow/.local/lib/python3.7/site-packages/airflow/models/dagbag.py", line 331, in _load_modules_from_file
    loader.exec_module(new_module)
  File "<frozen importlib._bootstrap_external>", line 728, in exec_module
  File "<frozen importlib._bootstrap>", line 219, in _call_with_frames_removed
  File "/opt/airflow/dags/gcs_ingestion_dag_NEWDATA.py", line 79, in <module>
    bash_command=f"curl -sSLf {dataset_url} > {path_to_local_home}/{dataset_archive}"
NameError: name 'dataset_url' is not defined
[2022-03-16 19:07:52,731] {processor.py:656} WARNING - No viable dags retrieved from /opt/airflow/dags/gcs_ingestion_dag_NEWDATA.py
[2022-03-16 19:07:52,737] {processor.py:171} INFO - Processing /opt/airflow/dags/gcs_ingestion_dag_NEWDATA.py took 0.489 seconds
[2022-03-16 19:08:23,568] {processor.py:163} INFO - Started process (PID=21635) to work on /opt/airflow/dags/gcs_ingestion_dag_NEWDATA.py
[2022-03-16 19:08:23,569] {processor.py:642} INFO - Processing file /opt/airflow/dags/gcs_ingestion_dag_NEWDATA.py for tasks to queue
[2022-03-16 19:08:23,569] {logging_mixin.py:109} INFO - [2022-03-16 19:08:23,569] {dagbag.py:500} INFO - Filling up the DagBag from /opt/airflow/dags/gcs_ingestion_dag_NEWDATA.py
[2022-03-16 19:08:24,122] {logging_mixin.py:109} INFO - [2022-03-16 19:08:24,121] {dagbag.py:334} ERROR - Failed to import: /opt/airflow/dags/gcs_ingestion_dag_NEWDATA.py
Traceback (most recent call last):
  File "/home/airflow/.local/lib/python3.7/site-packages/airflow/models/dagbag.py", line 331, in _load_modules_from_file
    loader.exec_module(new_module)
  File "<frozen importlib._bootstrap_external>", line 728, in exec_module
  File "<frozen importlib._bootstrap>", line 219, in _call_with_frames_removed
  File "/opt/airflow/dags/gcs_ingestion_dag_NEWDATA.py", line 79, in <module>
    bash_command=f"curl -sSLf {dataset_url} > {path_to_local_home}/{dataset_archive}"
NameError: name 'dataset_url' is not defined
[2022-03-16 19:08:24,130] {processor.py:656} WARNING - No viable dags retrieved from /opt/airflow/dags/gcs_ingestion_dag_NEWDATA.py
[2022-03-16 19:08:24,134] {processor.py:171} INFO - Processing /opt/airflow/dags/gcs_ingestion_dag_NEWDATA.py took 0.568 seconds
[2022-03-16 19:08:54,932] {processor.py:163} INFO - Started process (PID=21743) to work on /opt/airflow/dags/gcs_ingestion_dag_NEWDATA.py
[2022-03-16 19:08:54,934] {processor.py:642} INFO - Processing file /opt/airflow/dags/gcs_ingestion_dag_NEWDATA.py for tasks to queue
[2022-03-16 19:08:54,935] {logging_mixin.py:109} INFO - [2022-03-16 19:08:54,935] {dagbag.py:500} INFO - Filling up the DagBag from /opt/airflow/dags/gcs_ingestion_dag_NEWDATA.py
[2022-03-16 19:08:55,406] {logging_mixin.py:109} INFO - [2022-03-16 19:08:55,406] {dagbag.py:334} ERROR - Failed to import: /opt/airflow/dags/gcs_ingestion_dag_NEWDATA.py
Traceback (most recent call last):
  File "/home/airflow/.local/lib/python3.7/site-packages/airflow/models/dagbag.py", line 331, in _load_modules_from_file
    loader.exec_module(new_module)
  File "<frozen importlib._bootstrap_external>", line 728, in exec_module
  File "<frozen importlib._bootstrap>", line 219, in _call_with_frames_removed
  File "/opt/airflow/dags/gcs_ingestion_dag_NEWDATA.py", line 79, in <module>
    bash_command=f"curl -sSLf {dataset_url} > {path_to_local_home}/{dataset_archive}"
NameError: name 'dataset_url' is not defined
[2022-03-16 19:08:55,414] {processor.py:656} WARNING - No viable dags retrieved from /opt/airflow/dags/gcs_ingestion_dag_NEWDATA.py
[2022-03-16 19:08:55,420] {processor.py:171} INFO - Processing /opt/airflow/dags/gcs_ingestion_dag_NEWDATA.py took 0.489 seconds
[2022-03-16 19:09:26,076] {processor.py:163} INFO - Started process (PID=21857) to work on /opt/airflow/dags/gcs_ingestion_dag_NEWDATA.py
[2022-03-16 19:09:26,077] {processor.py:642} INFO - Processing file /opt/airflow/dags/gcs_ingestion_dag_NEWDATA.py for tasks to queue
[2022-03-16 19:09:26,078] {logging_mixin.py:109} INFO - [2022-03-16 19:09:26,078] {dagbag.py:500} INFO - Filling up the DagBag from /opt/airflow/dags/gcs_ingestion_dag_NEWDATA.py
[2022-03-16 19:09:26,587] {logging_mixin.py:109} INFO - [2022-03-16 19:09:26,586] {dagbag.py:334} ERROR - Failed to import: /opt/airflow/dags/gcs_ingestion_dag_NEWDATA.py
Traceback (most recent call last):
  File "/home/airflow/.local/lib/python3.7/site-packages/airflow/models/dagbag.py", line 331, in _load_modules_from_file
    loader.exec_module(new_module)
  File "<frozen importlib._bootstrap_external>", line 728, in exec_module
  File "<frozen importlib._bootstrap>", line 219, in _call_with_frames_removed
  File "/opt/airflow/dags/gcs_ingestion_dag_NEWDATA.py", line 79, in <module>
    bash_command=f"curl -sSLf {dataset_url} > {path_to_local_home}/{dataset_archive}"
NameError: name 'dataset_url' is not defined
[2022-03-16 19:09:26,594] {processor.py:656} WARNING - No viable dags retrieved from /opt/airflow/dags/gcs_ingestion_dag_NEWDATA.py
[2022-03-16 19:09:26,600] {processor.py:171} INFO - Processing /opt/airflow/dags/gcs_ingestion_dag_NEWDATA.py took 0.526 seconds
[2022-03-16 19:09:56,951] {processor.py:163} INFO - Started process (PID=21972) to work on /opt/airflow/dags/gcs_ingestion_dag_NEWDATA.py
[2022-03-16 19:09:56,953] {processor.py:642} INFO - Processing file /opt/airflow/dags/gcs_ingestion_dag_NEWDATA.py for tasks to queue
[2022-03-16 19:09:56,953] {logging_mixin.py:109} INFO - [2022-03-16 19:09:56,953] {dagbag.py:500} INFO - Filling up the DagBag from /opt/airflow/dags/gcs_ingestion_dag_NEWDATA.py
[2022-03-16 19:09:57,434] {logging_mixin.py:109} INFO - [2022-03-16 19:09:57,434] {dagbag.py:334} ERROR - Failed to import: /opt/airflow/dags/gcs_ingestion_dag_NEWDATA.py
Traceback (most recent call last):
  File "/home/airflow/.local/lib/python3.7/site-packages/airflow/models/dagbag.py", line 331, in _load_modules_from_file
    loader.exec_module(new_module)
  File "<frozen importlib._bootstrap_external>", line 728, in exec_module
  File "<frozen importlib._bootstrap>", line 219, in _call_with_frames_removed
  File "/opt/airflow/dags/gcs_ingestion_dag_NEWDATA.py", line 79, in <module>
    bash_command=f"curl -sSLf {dataset_url} > {path_to_local_home}/{dataset_archive}"
NameError: name 'dataset_url' is not defined
[2022-03-16 19:09:57,442] {processor.py:656} WARNING - No viable dags retrieved from /opt/airflow/dags/gcs_ingestion_dag_NEWDATA.py
[2022-03-16 19:09:57,447] {processor.py:171} INFO - Processing /opt/airflow/dags/gcs_ingestion_dag_NEWDATA.py took 0.497 seconds
[2022-03-16 19:10:28,289] {processor.py:163} INFO - Started process (PID=22077) to work on /opt/airflow/dags/gcs_ingestion_dag_NEWDATA.py
[2022-03-16 19:10:28,290] {processor.py:642} INFO - Processing file /opt/airflow/dags/gcs_ingestion_dag_NEWDATA.py for tasks to queue
[2022-03-16 19:10:28,291] {logging_mixin.py:109} INFO - [2022-03-16 19:10:28,291] {dagbag.py:500} INFO - Filling up the DagBag from /opt/airflow/dags/gcs_ingestion_dag_NEWDATA.py
[2022-03-16 19:10:28,775] {logging_mixin.py:109} INFO - [2022-03-16 19:10:28,774] {dagbag.py:334} ERROR - Failed to import: /opt/airflow/dags/gcs_ingestion_dag_NEWDATA.py
Traceback (most recent call last):
  File "/home/airflow/.local/lib/python3.7/site-packages/airflow/models/dagbag.py", line 331, in _load_modules_from_file
    loader.exec_module(new_module)
  File "<frozen importlib._bootstrap_external>", line 728, in exec_module
  File "<frozen importlib._bootstrap>", line 219, in _call_with_frames_removed
  File "/opt/airflow/dags/gcs_ingestion_dag_NEWDATA.py", line 79, in <module>
    bash_command=f"curl -sSLf {dataset_url} > {path_to_local_home}/{dataset_archive}"
NameError: name 'dataset_url' is not defined
[2022-03-16 19:10:28,783] {processor.py:656} WARNING - No viable dags retrieved from /opt/airflow/dags/gcs_ingestion_dag_NEWDATA.py
[2022-03-16 19:10:28,788] {processor.py:171} INFO - Processing /opt/airflow/dags/gcs_ingestion_dag_NEWDATA.py took 0.501 seconds
[2022-03-16 19:10:59,681] {processor.py:163} INFO - Started process (PID=22193) to work on /opt/airflow/dags/gcs_ingestion_dag_NEWDATA.py
[2022-03-16 19:10:59,683] {processor.py:642} INFO - Processing file /opt/airflow/dags/gcs_ingestion_dag_NEWDATA.py for tasks to queue
[2022-03-16 19:10:59,683] {logging_mixin.py:109} INFO - [2022-03-16 19:10:59,683] {dagbag.py:500} INFO - Filling up the DagBag from /opt/airflow/dags/gcs_ingestion_dag_NEWDATA.py
[2022-03-16 19:11:00,187] {logging_mixin.py:109} INFO - [2022-03-16 19:11:00,186] {dagbag.py:334} ERROR - Failed to import: /opt/airflow/dags/gcs_ingestion_dag_NEWDATA.py
Traceback (most recent call last):
  File "/home/airflow/.local/lib/python3.7/site-packages/airflow/models/dagbag.py", line 331, in _load_modules_from_file
    loader.exec_module(new_module)
  File "<frozen importlib._bootstrap_external>", line 728, in exec_module
  File "<frozen importlib._bootstrap>", line 219, in _call_with_frames_removed
  File "/opt/airflow/dags/gcs_ingestion_dag_NEWDATA.py", line 79, in <module>
    bash_command=f"curl -sSLf {dataset_url} > {path_to_local_home}/{dataset_archive}"
NameError: name 'dataset_url' is not defined
[2022-03-16 19:11:00,195] {processor.py:656} WARNING - No viable dags retrieved from /opt/airflow/dags/gcs_ingestion_dag_NEWDATA.py
[2022-03-16 19:11:00,200] {processor.py:171} INFO - Processing /opt/airflow/dags/gcs_ingestion_dag_NEWDATA.py took 0.521 seconds
[2022-03-16 19:11:31,033] {processor.py:163} INFO - Started process (PID=22310) to work on /opt/airflow/dags/gcs_ingestion_dag_NEWDATA.py
[2022-03-16 19:11:31,034] {processor.py:642} INFO - Processing file /opt/airflow/dags/gcs_ingestion_dag_NEWDATA.py for tasks to queue
[2022-03-16 19:11:31,035] {logging_mixin.py:109} INFO - [2022-03-16 19:11:31,035] {dagbag.py:500} INFO - Filling up the DagBag from /opt/airflow/dags/gcs_ingestion_dag_NEWDATA.py
[2022-03-16 19:11:31,524] {logging_mixin.py:109} INFO - [2022-03-16 19:11:31,523] {dagbag.py:334} ERROR - Failed to import: /opt/airflow/dags/gcs_ingestion_dag_NEWDATA.py
Traceback (most recent call last):
  File "/home/airflow/.local/lib/python3.7/site-packages/airflow/models/dagbag.py", line 331, in _load_modules_from_file
    loader.exec_module(new_module)
  File "<frozen importlib._bootstrap_external>", line 728, in exec_module
  File "<frozen importlib._bootstrap>", line 219, in _call_with_frames_removed
  File "/opt/airflow/dags/gcs_ingestion_dag_NEWDATA.py", line 79, in <module>
    bash_command=f"curl -sSLf {dataset_url} > {path_to_local_home}/{dataset_archive}"
NameError: name 'dataset_url' is not defined
[2022-03-16 19:11:31,532] {processor.py:656} WARNING - No viable dags retrieved from /opt/airflow/dags/gcs_ingestion_dag_NEWDATA.py
[2022-03-16 19:11:31,537] {processor.py:171} INFO - Processing /opt/airflow/dags/gcs_ingestion_dag_NEWDATA.py took 0.506 seconds
[2022-03-16 19:12:02,452] {processor.py:163} INFO - Started process (PID=22427) to work on /opt/airflow/dags/gcs_ingestion_dag_NEWDATA.py
[2022-03-16 19:12:02,454] {processor.py:642} INFO - Processing file /opt/airflow/dags/gcs_ingestion_dag_NEWDATA.py for tasks to queue
[2022-03-16 19:12:02,454] {logging_mixin.py:109} INFO - [2022-03-16 19:12:02,454] {dagbag.py:500} INFO - Filling up the DagBag from /opt/airflow/dags/gcs_ingestion_dag_NEWDATA.py
[2022-03-16 19:12:02,971] {logging_mixin.py:109} INFO - [2022-03-16 19:12:02,970] {dagbag.py:334} ERROR - Failed to import: /opt/airflow/dags/gcs_ingestion_dag_NEWDATA.py
Traceback (most recent call last):
  File "/home/airflow/.local/lib/python3.7/site-packages/airflow/models/dagbag.py", line 331, in _load_modules_from_file
    loader.exec_module(new_module)
  File "<frozen importlib._bootstrap_external>", line 728, in exec_module
  File "<frozen importlib._bootstrap>", line 219, in _call_with_frames_removed
  File "/opt/airflow/dags/gcs_ingestion_dag_NEWDATA.py", line 79, in <module>
    bash_command=f"curl -sSLf {dataset_url} > {path_to_local_home}/{dataset_archive}"
NameError: name 'dataset_url' is not defined
[2022-03-16 19:12:02,980] {processor.py:656} WARNING - No viable dags retrieved from /opt/airflow/dags/gcs_ingestion_dag_NEWDATA.py
[2022-03-16 19:12:02,986] {processor.py:171} INFO - Processing /opt/airflow/dags/gcs_ingestion_dag_NEWDATA.py took 0.535 seconds
[2022-03-16 19:12:33,852] {processor.py:163} INFO - Started process (PID=22532) to work on /opt/airflow/dags/gcs_ingestion_dag_NEWDATA.py
[2022-03-16 19:12:33,853] {processor.py:642} INFO - Processing file /opt/airflow/dags/gcs_ingestion_dag_NEWDATA.py for tasks to queue
[2022-03-16 19:12:33,854] {logging_mixin.py:109} INFO - [2022-03-16 19:12:33,854] {dagbag.py:500} INFO - Filling up the DagBag from /opt/airflow/dags/gcs_ingestion_dag_NEWDATA.py
[2022-03-16 19:12:34,329] {logging_mixin.py:109} INFO - [2022-03-16 19:12:34,329] {dagbag.py:334} ERROR - Failed to import: /opt/airflow/dags/gcs_ingestion_dag_NEWDATA.py
Traceback (most recent call last):
  File "/home/airflow/.local/lib/python3.7/site-packages/airflow/models/dagbag.py", line 331, in _load_modules_from_file
    loader.exec_module(new_module)
  File "<frozen importlib._bootstrap_external>", line 728, in exec_module
  File "<frozen importlib._bootstrap>", line 219, in _call_with_frames_removed
  File "/opt/airflow/dags/gcs_ingestion_dag_NEWDATA.py", line 79, in <module>
    bash_command=f"curl -sSLf {dataset_url} > {path_to_local_home}/{dataset_archive}"
NameError: name 'dataset_url' is not defined
[2022-03-16 19:12:34,337] {processor.py:656} WARNING - No viable dags retrieved from /opt/airflow/dags/gcs_ingestion_dag_NEWDATA.py
[2022-03-16 19:12:34,343] {processor.py:171} INFO - Processing /opt/airflow/dags/gcs_ingestion_dag_NEWDATA.py took 0.492 seconds
[2022-03-16 19:13:05,024] {processor.py:163} INFO - Started process (PID=22647) to work on /opt/airflow/dags/gcs_ingestion_dag_NEWDATA.py
[2022-03-16 19:13:05,030] {processor.py:642} INFO - Processing file /opt/airflow/dags/gcs_ingestion_dag_NEWDATA.py for tasks to queue
[2022-03-16 19:13:05,031] {logging_mixin.py:109} INFO - [2022-03-16 19:13:05,031] {dagbag.py:500} INFO - Filling up the DagBag from /opt/airflow/dags/gcs_ingestion_dag_NEWDATA.py
[2022-03-16 19:13:05,524] {logging_mixin.py:109} INFO - [2022-03-16 19:13:05,523] {dagbag.py:334} ERROR - Failed to import: /opt/airflow/dags/gcs_ingestion_dag_NEWDATA.py
Traceback (most recent call last):
  File "/home/airflow/.local/lib/python3.7/site-packages/airflow/models/dagbag.py", line 331, in _load_modules_from_file
    loader.exec_module(new_module)
  File "<frozen importlib._bootstrap_external>", line 728, in exec_module
  File "<frozen importlib._bootstrap>", line 219, in _call_with_frames_removed
  File "/opt/airflow/dags/gcs_ingestion_dag_NEWDATA.py", line 79, in <module>
    bash_command=f"curl -sSLf {dataset_url} > {path_to_local_home}/{dataset_archive}"
NameError: name 'dataset_url' is not defined
[2022-03-16 19:13:05,532] {processor.py:656} WARNING - No viable dags retrieved from /opt/airflow/dags/gcs_ingestion_dag_NEWDATA.py
[2022-03-16 19:13:05,537] {processor.py:171} INFO - Processing /opt/airflow/dags/gcs_ingestion_dag_NEWDATA.py took 0.515 seconds
[2022-03-16 19:13:36,204] {processor.py:163} INFO - Started process (PID=22761) to work on /opt/airflow/dags/gcs_ingestion_dag_NEWDATA.py
[2022-03-16 19:13:36,212] {processor.py:642} INFO - Processing file /opt/airflow/dags/gcs_ingestion_dag_NEWDATA.py for tasks to queue
[2022-03-16 19:13:36,213] {logging_mixin.py:109} INFO - [2022-03-16 19:13:36,213] {dagbag.py:500} INFO - Filling up the DagBag from /opt/airflow/dags/gcs_ingestion_dag_NEWDATA.py
[2022-03-16 19:13:36,772] {logging_mixin.py:109} INFO - [2022-03-16 19:13:36,772] {dagbag.py:334} ERROR - Failed to import: /opt/airflow/dags/gcs_ingestion_dag_NEWDATA.py
Traceback (most recent call last):
  File "/home/airflow/.local/lib/python3.7/site-packages/airflow/models/dagbag.py", line 331, in _load_modules_from_file
    loader.exec_module(new_module)
  File "<frozen importlib._bootstrap_external>", line 728, in exec_module
  File "<frozen importlib._bootstrap>", line 219, in _call_with_frames_removed
  File "/opt/airflow/dags/gcs_ingestion_dag_NEWDATA.py", line 79, in <module>
    bash_command=f"curl -sSLf {dataset_url} > {path_to_local_home}/{dataset_archive}"
NameError: name 'dataset_url' is not defined
[2022-03-16 19:13:36,780] {processor.py:656} WARNING - No viable dags retrieved from /opt/airflow/dags/gcs_ingestion_dag_NEWDATA.py
[2022-03-16 19:13:36,785] {processor.py:171} INFO - Processing /opt/airflow/dags/gcs_ingestion_dag_NEWDATA.py took 0.582 seconds
[2022-03-16 19:14:07,340] {processor.py:163} INFO - Started process (PID=22867) to work on /opt/airflow/dags/gcs_ingestion_dag_NEWDATA.py
[2022-03-16 19:14:07,342] {processor.py:642} INFO - Processing file /opt/airflow/dags/gcs_ingestion_dag_NEWDATA.py for tasks to queue
[2022-03-16 19:14:07,342] {logging_mixin.py:109} INFO - [2022-03-16 19:14:07,342] {dagbag.py:500} INFO - Filling up the DagBag from /opt/airflow/dags/gcs_ingestion_dag_NEWDATA.py
[2022-03-16 19:14:07,843] {logging_mixin.py:109} INFO - [2022-03-16 19:14:07,842] {dagbag.py:334} ERROR - Failed to import: /opt/airflow/dags/gcs_ingestion_dag_NEWDATA.py
Traceback (most recent call last):
  File "/home/airflow/.local/lib/python3.7/site-packages/airflow/models/dagbag.py", line 331, in _load_modules_from_file
    loader.exec_module(new_module)
  File "<frozen importlib._bootstrap_external>", line 728, in exec_module
  File "<frozen importlib._bootstrap>", line 219, in _call_with_frames_removed
  File "/opt/airflow/dags/gcs_ingestion_dag_NEWDATA.py", line 79, in <module>
    bash_command=f"curl -sSLf {dataset_url} > {path_to_local_home}/{dataset_archive}"
NameError: name 'dataset_url' is not defined
[2022-03-16 19:14:07,851] {processor.py:656} WARNING - No viable dags retrieved from /opt/airflow/dags/gcs_ingestion_dag_NEWDATA.py
[2022-03-16 19:14:07,855] {processor.py:171} INFO - Processing /opt/airflow/dags/gcs_ingestion_dag_NEWDATA.py took 0.517 seconds
[2022-03-16 19:14:38,538] {processor.py:163} INFO - Started process (PID=22982) to work on /opt/airflow/dags/gcs_ingestion_dag_NEWDATA.py
[2022-03-16 19:14:38,539] {processor.py:642} INFO - Processing file /opt/airflow/dags/gcs_ingestion_dag_NEWDATA.py for tasks to queue
[2022-03-16 19:14:38,539] {logging_mixin.py:109} INFO - [2022-03-16 19:14:38,539] {dagbag.py:500} INFO - Filling up the DagBag from /opt/airflow/dags/gcs_ingestion_dag_NEWDATA.py
[2022-03-16 19:14:39,054] {logging_mixin.py:109} INFO - [2022-03-16 19:14:39,054] {dagbag.py:334} ERROR - Failed to import: /opt/airflow/dags/gcs_ingestion_dag_NEWDATA.py
Traceback (most recent call last):
  File "/home/airflow/.local/lib/python3.7/site-packages/airflow/models/dagbag.py", line 331, in _load_modules_from_file
    loader.exec_module(new_module)
  File "<frozen importlib._bootstrap_external>", line 728, in exec_module
  File "<frozen importlib._bootstrap>", line 219, in _call_with_frames_removed
  File "/opt/airflow/dags/gcs_ingestion_dag_NEWDATA.py", line 79, in <module>
    bash_command=f"curl -sSLf {dataset_url} > {path_to_local_home}/{dataset_archive}"
NameError: name 'dataset_url' is not defined
[2022-03-16 19:14:39,062] {processor.py:656} WARNING - No viable dags retrieved from /opt/airflow/dags/gcs_ingestion_dag_NEWDATA.py
[2022-03-16 19:14:39,068] {processor.py:171} INFO - Processing /opt/airflow/dags/gcs_ingestion_dag_NEWDATA.py took 0.532 seconds
[2022-03-16 19:15:09,791] {processor.py:163} INFO - Started process (PID=23097) to work on /opt/airflow/dags/gcs_ingestion_dag_NEWDATA.py
[2022-03-16 19:15:09,792] {processor.py:642} INFO - Processing file /opt/airflow/dags/gcs_ingestion_dag_NEWDATA.py for tasks to queue
[2022-03-16 19:15:09,793] {logging_mixin.py:109} INFO - [2022-03-16 19:15:09,793] {dagbag.py:500} INFO - Filling up the DagBag from /opt/airflow/dags/gcs_ingestion_dag_NEWDATA.py
[2022-03-16 19:15:10,311] {logging_mixin.py:109} INFO - [2022-03-16 19:15:10,311] {dagbag.py:334} ERROR - Failed to import: /opt/airflow/dags/gcs_ingestion_dag_NEWDATA.py
Traceback (most recent call last):
  File "/home/airflow/.local/lib/python3.7/site-packages/airflow/models/dagbag.py", line 331, in _load_modules_from_file
    loader.exec_module(new_module)
  File "<frozen importlib._bootstrap_external>", line 728, in exec_module
  File "<frozen importlib._bootstrap>", line 219, in _call_with_frames_removed
  File "/opt/airflow/dags/gcs_ingestion_dag_NEWDATA.py", line 79, in <module>
    bash_command=f"curl -sSLf {dataset_url} > {path_to_local_home}/{dataset_archive}"
NameError: name 'dataset_url' is not defined
[2022-03-16 19:15:10,319] {processor.py:656} WARNING - No viable dags retrieved from /opt/airflow/dags/gcs_ingestion_dag_NEWDATA.py
[2022-03-16 19:15:10,325] {processor.py:171} INFO - Processing /opt/airflow/dags/gcs_ingestion_dag_NEWDATA.py took 0.536 seconds
[2022-03-16 19:15:41,018] {processor.py:163} INFO - Started process (PID=23202) to work on /opt/airflow/dags/gcs_ingestion_dag_NEWDATA.py
[2022-03-16 19:15:41,020] {processor.py:642} INFO - Processing file /opt/airflow/dags/gcs_ingestion_dag_NEWDATA.py for tasks to queue
[2022-03-16 19:15:41,020] {logging_mixin.py:109} INFO - [2022-03-16 19:15:41,020] {dagbag.py:500} INFO - Filling up the DagBag from /opt/airflow/dags/gcs_ingestion_dag_NEWDATA.py
[2022-03-16 19:15:41,522] {logging_mixin.py:109} INFO - [2022-03-16 19:15:41,521] {dagbag.py:334} ERROR - Failed to import: /opt/airflow/dags/gcs_ingestion_dag_NEWDATA.py
Traceback (most recent call last):
  File "/home/airflow/.local/lib/python3.7/site-packages/airflow/models/dagbag.py", line 331, in _load_modules_from_file
    loader.exec_module(new_module)
  File "<frozen importlib._bootstrap_external>", line 728, in exec_module
  File "<frozen importlib._bootstrap>", line 219, in _call_with_frames_removed
  File "/opt/airflow/dags/gcs_ingestion_dag_NEWDATA.py", line 79, in <module>
    bash_command=f"curl -sSLf {dataset_url} > {path_to_local_home}/{dataset_archive}"
NameError: name 'dataset_url' is not defined
[2022-03-16 19:15:41,530] {processor.py:656} WARNING - No viable dags retrieved from /opt/airflow/dags/gcs_ingestion_dag_NEWDATA.py
[2022-03-16 19:15:41,536] {processor.py:171} INFO - Processing /opt/airflow/dags/gcs_ingestion_dag_NEWDATA.py took 0.520 seconds
